Workbook

Sheet student_performance_interaction
A1: student_id | B1: final_score | C1: grade | D1: pass_fail | E1: previous_score | F1: math_prev_score | G1: science_prev_score | H1: language_prev_score | I1: daily_study_hours | J1: attendance_percentage | K1: homework_completion_rate | L1: sleep_hours | M1: screen_time_hours | N1: physical_activity_minutes | O1: motivation_score | P1: exam_anxiety_score | Q1: parent_education_level | R1: study_environment
A2: S0001 | B2: 60.137241 | C2: D | D2: 1 | E2: 60.599707 | F2: 61.488212 | G2: 53.568119 | H2: 64.972292 | I2: 1.4272028 | J2: 75.738405 | K2: 68.534371 | L2: 6.8093521 | M2: 3.3130964 | N2: 65.059425 | O2: 4.1500247 | P2: 6.104103 | Q2: Master | R2: Noisy
A3: S0002 | B3: 99.021977 | C3: A | D3: 1 | E3: 92.289287 | F3: 85.612565 | G3: 91.873759 | H3: 89.040461 | I3: 4.8136115 | J3: 89.602736 | K3: 91.990197 | L3: 5.5677935 | M3: 4.9253593 | N3: 76.016617 | O3: 8.7146929 | P3: 1.9823581 | Q3: High School | R3: Quiet
A4: S0003 | B4: 70.522955 | C4: C | D4: 1 | E4: 80.259667 | F4: 82.160656 | G4: 72.736065 | H4: 74.243663 | I4: 1.2409078 | J4: 81.495426 | K4: 69.669666 | L4: 6.702875 | M4: 5.1078885 | N4: 113.61687 | O4: 5.9282197 | P4: 4.4636615 | Q4: High School | R4: Moderate
A5: S0004 | B5: 63.448537 | C5: D | D5: 1 | E5: 72.926217 | F5: 75.979145 | G5: 76.726496 | H5: 67.715995 | I5: 2.1906011 | J5: 71.472047 | K5: 71.976757 | L5: 7.8544386 | M5: 3.7724456 | N5: 108.68669 | O5: 4.2249277 | P5: 4.7404743 | Q5: High School | R5: Noisy
A6: S0005 | B6: 66.483019 | C6: C | D6: 1 | E6: 48.581025 | F6: 51.379977 | G6: 48.993224 | H6: 46.145011 | I6: 2.1922648 | J6: 64.276582 | K6: 68.940591 | L6: 7.6624289 | M6: 1.8989891 | N6: 42.107294 | O6: 9.5068152 | P6: 1.1438524 | Q6: Master | R6: Quiet
A7: S0006 | B7: 49.088061 | C7: F | D7: 0 | E7: 48.579699 | F7: 53.983602 | G7: 41.291941 | H7: 46.820092 | I7: 2.2816051 | J7: 61.624397 | K7: 71.320143 | L7: 7.3029304 | M7: 3.3387912 | N7: 45.551069 | O7: 4.837854 | P7: 5.588057 | Q7: Bachelor | R7: Noisy
A8: S0007 | B8: 48.453234 | C8: F | D8: 0 | E8: 43.194599 | F8: 47.364209 | G8: 41.648553 | H8: 39.344618 | I8: 1.6571474 | J8: 59.87698 | K8: 70.61607 | L8: 6.5341139 | M8: 5.8403625 | N8: 62.187649 | O8: 7.3106757 | P8: 1.6186579 | Q8: Master | R8: Quiet
A9: S0008 | B9: 84.613576 | C9: B | D9: 1 | E9: 87.639688 | F9: 89.935588 | G9: 83.878906 | H9: 81.159105 | I9: 4.1326457 | J9: 81.947173 | K9: 88.404181 | L9: 6.769044 | M9: 4.764931 | N9: 56.166948 | O9: 5.6443252 | P9: 3.5713538 | Q9: Bachelor | R9: Quiet
A10: S0009 | B10: 66.451909 | C10: C | D10: 1 | E10: 73.061326 | F10: 72.710497 | G10: 74.657198 | H10: 70.780722 | I10: 1.4899914 | J10: 71.631035 | K10: 61.153126 | L10: 6.9490891 | M10: 5.055813 | N10: 85.329386 | O10: 4.3911568 | P10: 6.2973392 | Q10: Master | R10: Moderate
A11: S0010 | B11: 74.20951 | C11: C | D11: 1 | E11: 78.943992 | F11: 70.639187 | G11: 85.646244 | H11: 79.851125 | I11: 3.5396266 | J11: 69.685303 | K11: 84.288583 | L11: 7.8484486 | M11: 1.1641275 | N11: 111.24984 | O11: 4.2995349 | P11: 5.4659576 | Q11: Master | R11: Quiet
A12: S0011 | B12: 42.715954 | C12: F | D12: 0 | E12: 41.132147 | F12: 43.280238 | G12: 31.756285 | H12: 44.107295 | I12: 1.4953841 | J12: 57.225358 | K12: 59.069031 | L12: 6.8418722 | M12: 3.3392973 | N12: 116.60624 | O12: 4.6933402 | P12: 6.8958071 | Q12: Bachelor | R12: Quiet
A13: S0012 | B13: 76.547557 | C13: C | D13: 1 | E13: 93.345042 | F13: 94.38348 | G13: 93.920172 | H13: 90.557927 | I13: 1.2821426 | J13: 87.639418 | K13: 71.924145 | L13: 6.3320738 | M13: 4.2331057 | N13: 88.824266 | O13: 4.4282021 | P13: 6.0729272 | Q13: Master | R13: Quiet
... A1001: S1000 | B1001: 64.350338 | C1001: D | D1001: 1 | E1001: 64.530318 | F1001: 61.068213 | G1001: 66.927525 | H1001: 64.099969 | I1001: 1.845725 | J1001: 75.801316 | K1001: 71.907619 | L1001: 5.7781016 | M1001: 5.8800696 | N1001: 117.28387 | O1001: 5.6722441 | P1001: 4.6438437 | Q1001: High School | R1001: Quiet

Sheet EDA
D1: Percentile
A2: Maximum | B2: =MAX(Table1[final_score]) -> 100 | D2: 0.1 | E2: =PERCENTILE(Table1[final_score],EDA!D2) -> 51.966411 | G2: 10 | H2: =COUNTIF(Table1[final_score],"<10") -> 0
A3: Minimum | B3: =MIN(Table1[final_score]) -> 37.364699 | D3: 0.2 | E3: =PERCENTILE(Table1[final_score],EDA!D3) -> 57.315705 | G3: 20 | H3: =COUNTIFS(Table1[final_score],">=10",Table1[final_score],"<20") -> 0
A4: Range | B4: =B2-B3 -> 62.635301 | D4: 0.3 | E4: =PERCENTILE(Table1[final_score],EDA!D4) -> 61.822146 | G4: 30 | H4: =COUNTIFS(Table1[final_score],">=20",Table1[final_score],"<30") -> 0
A5: Average/Mean | B5: =AVERAGE(Table1[final_score]) -> 70.935159 | D5: 0.4 | E5: =PERCENTILE(Table1[final_score],EDA!D5) -> 66.092365 | G5: 40 | H5: =COUNTIFS(Table1[final_score],">=30",Table1[final_score],"<40") -> 7
A6: Median | B6: =MEDIAN(Table1[final_score]) -> 70.673531 | D6: 0.5 | E6: =PERCENTILE(Table1[final_score],EDA!D6) -> 70.673531 | G6: 50 | H6: =COUNTIFS(Table1[final_score],">=40",Table1[final_score],"<50") -> 63
A7: Count | B7: =COUNT(Table1[final_score]) -> 1000 | D7: 0.6 | E7: =PERCENTILE(Table1[final_score],EDA!D7) -> 75.135239 | G7: 60 | H7: =COUNTIFS(Table1[final_score],">=50",Table1[final_score],"<60") -> 178
D8: 0.7 | E8: =PERCENTILE(Table1[final_score],EDA!D8) -> 79.486433 | G8: 70 | H8: =COUNTIFS(Table1[final_score],">=60",Table1[final_score],"<70") -> 230
D9: 0.8 | E9: =PERCENTILE(Table1[final_score],EDA!D9) -> 84.475031 | G9: 80 | H9: =COUNTIFS(Table1[final_score],">=70",Table1[final_score],"<80") -> 234
D10: 0.9 | E10: =PERCENTILE(Table1[final_score],EDA!D10) -> 90.608812 | G10: 90 | H10: =COUNTIFS(Table1[final_score],">=80",Table1[final_score],"<90") -> 182
D11: 1 | E11: =PERCENTILE(Table1[final_score],EDA!D11) -> 100 | G11: 100 | H11: =COUNTIF(Table1[final_score],">90") -> 106

Sheet Sheet4
A1: final_score | B1: daily_study_hours | D1: previous_score | E1: final_score | G1: student_id | H1: screen time | I1: final Score | L1: final_score | M1: daily_study_hours | P1: Motivation Score | Q1: final Score
A2: 60.137241 | B2: 1.4272028 | D2: 60.599707 | E2: 60.137241 | G2: S0001 | H2: =VLOOKUP(G2,Table1[#All],13,FALSE) -> 3.3130964 | I2: =VLOOKUP(G2,Table1[#All],5,FALSE) -> 60.599707 | K2: final_score | L2: 1 | O2: Motivation Score | P2: 1
A3: 99.021977 | B3: 4.8136115 | D3: 92.289287 | E3: 99.021977 | G3: S0002 | H3: =VLOOKUP(G3,Table1[#All],13,FALSE) -> 4.9253593 | I3: =VLOOKUP(G3,Table1[#All],5,FALSE) -> 92.289287 | K3: daily_study_hours | L3: 0.35727494 | M3: 1 | O3: final Score | P3: -0.0326304 | Q3: 1
A4: 70.522955 | B4: 1.2409078 | D4: 80.259667 | E4: 70.522955 | G4: S0003 | H4: =VLOOKUP(G4,Table1[#All],13,FALSE) -> 5.1078885 | I4: =VLOOKUP(G4,Table1[#All],5,FALSE) -> 80.259667
A5: 63.448537 | B5: 2.1906011 | D5: 72.926217 | E5: 63.448537 | G5: S0004 | H5: =VLOOKUP(G5,Table1[#All],13,FALSE) -> 3.7724456 | I5: =VLOOKUP(G5,Table1[#All],5,FALSE) -> 72.926217
A6: 66.483019 | B6: 2.1922648 | D6: 48.581025 | E6: 66.483019 | G6: S0005 | H6: =VLOOKUP(G6,Table1[#All],13,FALSE) -> 1.8989891 | I6: =VLOOKUP(G6,Table1[#All],5,FALSE) -> 48.581025 | L6: previous_score | M6: final_score | P6: Anxiety Score | Q6: final Score
A7: 49.088061 | B7: 2.2816051 | D7: 48.579699 | E7: 49.088061 | G7: S0006 | H7: =VLOOKUP(G7,Table1[#All],13,FALSE) -> 3.3387912 | I7: =VLOOKUP(G7,Table1[#All],5,FALSE) -> 48.579699 | K7: previous_score | L7: 1 | O7: Anxiety Score | P7: 1
A8: 48.453234 | B8: 1.6571474 | D8: 43.194599 | E8: 48.453234 | G8: S0007 | H8: =VLOOKUP(G8,Table1[#All],13,FALSE) -> 5.8403625 | I8: =VLOOKUP(G8,Table1[#All],5,FALSE) -> 43.194599 | K8: final_score | L8: 0.84375515 | M8: 1 | O8: final Score | P8: 0.025017805 | Q8: 1
A9: 84.613576 | B9: 4.1326457 | D9: 87.639688 | E9: 84.613576 | G9: S0008 | H9: =VLOOKUP(G9,Table1[#All],13,FALSE) -> 4.764931 | I9: =VLOOKUP(G9,Table1[#All],5,FALSE) -> 87.639688
A10: 66.451909 | B10: 1.4899914 | D10: 73.061326 | E10: 66.451909 | G10: S0009 | H10: =VLOOKUP(G10,Table1[#All],13,FALSE) -> 5.055813 | I10: =VLOOKUP(G10,Table1[#All],5,FALSE) -> 73.061326
A11: 74.20951 | B11: 3.5396266 | D11: 78.943992 | E11: 74.20951 | G11: S0010 | H11: =VLOOKUP(G11,Table1[#All],13,FALSE) -> 1.1641275 | I11: =VLOOKUP(G11,Table1[#All],5,FALSE) -> 78.943992 | L11: Parent Education | M11: final Score | P11: screen time | Q11: final Score
A12: 42.715954 | B12: 1.4953841 | D12: 41.132147 | E12: 42.715954 | G12: S0011 | H12: =VLOOKUP(G12,Table1[#All],13,FALSE) -> 3.3392973 | I12: =VLOOKUP(G12,Table1[#All],5,FALSE) -> 41.132147 | K12: Parent Education | L12: 1 | O12: screen time | P12: 1
A13: 76.547557 | B13: 1.2821426 | D13: 93.345042 | E13: 76.547557 | G13: S0012 | H13: =VLOOKUP(G13,Table1[#All],13,FALSE) -> 4.2331057 | I13: =VLOOKUP(G13,Table1[#All],5,FALSE) -> 93.345042 | K13: final Score | L13: 0.097768154 | M13: 1 | O13: final Score | P13: 0.017685322 | Q13: 1
A14: 97.925131 | B14: 4.637718 | D14: 85.784345 | E14: 97.925131 | G14: S0013 | H14: =VLOOKUP(G14,Table1[#All],13,FALSE) -> 5.1501634 | I14: =VLOOKUP(G14,Table1[#All],5,FALSE) -> 85.784345
A15: 56.731838 | B15: 1.7605151 | D15: 51.678651 | E15: 56.731838 | G15: S0014 | H15: =VLOOKUP(G15,Table1[#All],13,FALSE) -> 1.2463683 | I15: =VLOOKUP(G15,Table1[#All],5,FALSE) -> 51.678651
A16: 55.269319 | B16: 4.2850006 | D16: 50.000373 | E16: 55.269319 | G16: S0015 | H16: =VLOOKUP(G16,Table1[#All],13,FALSE) -> 5.2621944 | I16: =VLOOKUP(G16,Table1[#All],5,FALSE) -> 50.000373 | L16: Sleep Hour | M16: final Score
A17: 58.383835 | B17: 3.1785235 | D17: 50.087248 | E17: 58.383835 | G17: S0016 | H17: =VLOOKUP(G17,Table1[#All],13,FALSE) -> 3.7420047 | I17: =VLOOKUP(G17,Table1[#All],5,FALSE) -> 50.087248 | K17: Sleep Hour | L17: 1
A18: 53.472483 | B18: 1.3114261 | D18: 56.733323 | E18: 53.472483 | G18: S0017 | H18: =VLOOKUP(G18,Table1[#All],13,FALSE) -> 1.9865699 | I18: =VLOOKUP(G18,Table1[#All],5,FALSE) -> 56.733323 | K18: final Score | L18: -0.0326304 | M18: 1
A19: 81.738245 | B19: 4.8217928 | D19: 68.861604 | E19: 81.738245 | G19: S0018 | H19: =VLOOKUP(G19,Table1[#All],13,FALSE) -> 2.5862761 | I19: =VLOOKUP(G19,Table1[#All],5,FALSE) -> 68.861604
A20: 61.010618 | B20: 1.9878447 | D20: 63.756976 | E20: 61.010618 | G20: S0019 | H20: =VLOOKUP(G20,Table1[#All],13,FALSE) -> 2.4096478 | I20: =VLOOKUP(G20,Table1[#All],5,FALSE) -> 63.756976
A21: 84.094984 | B21: 4.4385814 | D21: 56.017603 | E21: 84.094984 | G21: S0020 | H21: =VLOOKUP(G21,Table1[#All],13,FALSE) -> 3.6542952 | I21: =VLOOKUP(G21,Table1[#All],5,FALSE) -> 56.017603
A22: 63.394595 | B22: 1.67524 | D22: 73.651909 | E22: 63.394595 | G22: S0021 | H22: =VLOOKUP(G22,Table1[#All],13,FALSE) -> 1.2584284 | I22: =VLOOKUP(G22,Table1[#All],5,FALSE) -> 73.651909
A23: 74.755267 | B23: 4.4157715 | D23: 47.672162 | E23: 74.755267 | G23: S0022 | H23: =VLOOKUP(G23,Table1[#All],13,FALSE) -> 1.7926808 | I23: =VLOOKUP(G23,Table1[#All],5,FALSE) -> 47.672162
A24: 57.292057 | B24: 1.0529153 | D24: 56.067956 | E24: 57.292057 | G24: S0023 | H24: =VLOOKUP(G24,Table1[#All],13,FALSE) -> 5.0634652 | I24: =VLOOKUP(G24,Table1[#All],5,FALSE) -> 56.067956
A25: 66.167282 | B25: 3.0471218 | D25: 60.149901 | E25: 66.167282 | G25: S0024 | H25: =VLOOKUP(G25,Table1[#All],13,FALSE) -> 1.66302 | I25: =VLOOKUP(G25,Table1[#All],5,FALSE) -> 60.149901
A26: 77.100187 | B26: 4.0777703 | D26: 65.083849 | E26: 77.100187 | G26: S0025 | H26: =VLOOKUP(G26,Table1[#All],13,FALSE) -> 2.1669813 | I26: =VLOOKUP(G26,Table1[#All],5,FALSE) -> 65.083849
A27: 84.888241 | B27: 4.7391821 | D27: 83.184678 | E27: 84.888241 | G27: S0026 | H27: =VLOOKUP(G27,Table1[#All],13,FALSE) -> 3.266853 | I27: =VLOOKUP(G27,Table1[#All],5,FALSE) -> 83.184678
A28: 65.141653 | B28: 4.6368085 | D28: 50.982058 | E28: 65.141653 | G28: S0027 | H28: =VLOOKUP(G28,Table1[#All],13,FALSE) -> 3.5856044 | I28: =VLOOKUP(G28,Table1[#All],5,FALSE) -> 50.982058
A29: 80.093884 | B29: 4.2784995 | D29: 68.282894 | E29: 80.093884 | G29: S0028 | H29: =VLOOKUP(G29,Table1[#All],13,FALSE) -> 4.8180524 | I29: =VLOOKUP(G29,Table1[#All],5,FALSE) -> 68.282894
A30: 84.428594 | B30: 4.5527654 | D30: 72.582801 | E30: 84.428594 | G30: S0029 | H30: =VLOOKUP(G30,Table1[#All],13,FALSE) -> 3.2366621 | I30: =VLOOKUP(G30,Table1[#All],5,FALSE) -> 72.582801
... A1001: 64.350338 | B1001: 1.845725 | D1001: 64.530318 | E1001: 64.350338 | G1001: S1000 | H1001: =VLOOKUP(G1001,Table1[#All],13,FALSE) -> 5.8800696 | I1001: =VLOOKUP(G1001,Table1[#All],5,FALSE) -> 64.530318

Sheet Inferential Statistics
A1: student_id | B1: Final Score | C1: attendance_percentage | D1: y=0.4892x=38.572 | K1: Final Score | L1: previous_score | M1: y = 0.943x + 0.0717 | W1: final_score | X1: language_prev_score | Y1: y = 0.942x + 0.0844
A2: S0001 | B2: =VLOOKUP(A2,Table1[#All],2,FALSE) -> 60.137241 | C2: =VLOOKUP(A2,Table1[#All],10,FALSE) -> 75.738405 | D2: =0.4892*C2 + 38.572 -> 75.623228 | K2: =VLOOKUP(A2,Table1[#All],2,FALSE) -> 60.137241 | L2: =VLOOKUP(A2,Table1[],5,FALSE) -> 60.599707 | M2: =0.943*L2 + 0.0717 -> 57.217223 | W2: 60.137241 | X2: 64.972292 | Y2: =0.942*X2 + 0.0844 -> 61.288299
A3: S0002 | B3: =VLOOKUP(A3,Table1[#All],2,FALSE) -> 99.021977 | C3: =VLOOKUP(A3,Table1[#All],10,FALSE) -> 89.602736 | D3: =0.4892*C3 + 38.572 -> 82.405659 | K3: =VLOOKUP(A3,Table1[#All],2,FALSE) -> 99.021977 | L3: =VLOOKUP(A3,Table1[],5,FALSE) -> 92.289287 | M3: =0.943*L3 + 0.0717 -> 87.100498 | W3: 99.021977 | X3: 89.040461 | Y3: =0.942*X3 + 0.0844 -> 83.960514
A4: S0003 | B4: =VLOOKUP(A4,Table1[#All],2,FALSE) -> 70.522955 | C4: =VLOOKUP(A4,Table1[#All],10,FALSE) -> 81.495426 | D4: =0.4892*C4 + 38.572 -> 78.439562 | K4: =VLOOKUP(A4,Table1[#All],2,FALSE) -> 70.522955 | L4: =VLOOKUP(A4,Table1[],5,FALSE) -> 80.259667 | M4: =0.943*L4 + 0.0717 -> 75.756566 | W4: 70.522955 | X4: 74.243663 | Y4: =0.942*X4 + 0.0844 -> 70.02193
A5: S0004 | B5: =VLOOKUP(A5,Table1[#All],2,FALSE) -> 63.448537 | C5: =VLOOKUP(A5,Table1[#All],10,FALSE) -> 71.472047 | D5: =0.4892*C5 + 38.572 -> 73.536125 | K5: =VLOOKUP(A5,Table1[#All],2,FALSE) -> 63.448537 | L5: =VLOOKUP(A5,Table1[],5,FALSE) -> 72.926217 | M5: =0.943*L5 + 0.0717 -> 68.841122 | W5: 63.448537 | X5: 67.715995 | Y5: =0.942*X5 + 0.0844 -> 63.872867
A6: S0005 | B6: =VLOOKUP(A6,Table1[#All],2,FALSE) -> 66.483019 | C6: =VLOOKUP(A6,Table1[#All],10,FALSE) -> 64.276582 | D6: =0.4892*C6 + 38.572 -> 70.016104 | K6: =VLOOKUP(A6,Table1[#All],2,FALSE) -> 66.483019 | L6: =VLOOKUP(A6,Table1[],5,FALSE) -> 48.581025 | M6: =0.943*L6 + 0.0717 -> 45.883607 | W6: 66.483019 | X6: 46.145011 | Y6: =0.942*X6 + 0.0844 -> 43.553
A7: S0006 | B7: =VLOOKUP(A7,Table1[#All],2,FALSE) -> 49.088061 | C7: =VLOOKUP(A7,Table1[#All],10,FALSE) -> 61.624397 | D7: =0.4892*C7 + 38.572 -> 68.718655 | K7: =VLOOKUP(A7,Table1[#All],2,FALSE) -> 49.088061 | L7: =VLOOKUP(A7,Table1[],5,FALSE) -> 48.579699 | M7: =0.943*L7 + 0.0717 -> 45.882356 | W7: 49.088061 | X7: 46.820092 | Y7: =0.942*X7 + 0.0844 -> 44.188927
A8: S0007 | B8: =VLOOKUP(A8,Table1[#All],2,FALSE) -> 48.453234 | C8: =VLOOKUP(A8,Table1[#All],10,FALSE) -> 59.87698 | D8: =0.4892*C8 + 38.572 -> 67.863818 | K8: =VLOOKUP(A8,Table1[#All],2,FALSE) -> 48.453234 | L8: =VLOOKUP(A8,Table1[],5,FALSE) -> 43.194599 | M8: =0.943*L8 + 0.0717 -> 40.804207 | W8: 48.453234 | X8: 39.344618 | Y8: =0.942*X8 + 0.0844 -> 37.14703
A9: S0008 | B9: =VLOOKUP(A9,Table1[#All],2,FALSE) -> 84.613576 | C9: =VLOOKUP(A9,Table1[#All],10,FALSE) -> 81.947173 | D9: =0.4892*C9 + 38.572 -> 78.660557 | K9: =VLOOKUP(A9,Table1[#All],2,FALSE) -> 84.613576 | L9: =VLOOKUP(A9,Table1[],5,FALSE) -> 87.639688 | M9: =0.943*L9 + 0.0717 -> 82.715926 | W9: 84.613576 | X9: 81.159105 | Y9: =0.942*X9 + 0.0844 -> 76.536277
A10: S0009 | B10: =VLOOKUP(A10,Table1[#All],2,FALSE) -> 66.451909 | C10: =VLOOKUP(A10,Table1[#All],10,FALSE) -> 71.631035 | D10: =0.4892*C10 + 38.572 -> 73.613902 | K10: =VLOOKUP(A10,Table1[#All],2,FALSE) -> 66.451909 | L10: =VLOOKUP(A10,Table1[],5,FALSE) -> 73.061326 | M10: =0.943*L10 + 0.0717 -> 68.96853 | W10: 66.451909 | X10: 70.780722 | Y10: =0.942*X10 + 0.0844 -> 66.75984
A11: S0010 | B11: =VLOOKUP(A11,Table1[#All],2,FALSE) -> 74.20951 | C11: =VLOOKUP(A11,Table1[#All],10,FALSE) -> 69.685303 | D11: =0.4892*C11 + 38.572 -> 72.66205 | K11: =VLOOKUP(A11,Table1[#All],2,FALSE) -> 74.20951 | L11: =VLOOKUP(A11,Table1[],5,FALSE) -> 78.943992 | M11: =0.943*L11 + 0.0717 -> 74.515884 | W11: 74.20951 | X11: 79.851125 | Y11: =0.942*X11 + 0.0844 -> 75.30416
A12: S0011 | B12: =VLOOKUP(A12,Table1[#All],2,FALSE) -> 42.715954 | C12: =VLOOKUP(A12,Table1[#All],10,FALSE) -> 57.225358 | D12: =0.4892*C12 + 38.572 -> 66.566645 | K12: =VLOOKUP(A12,Table1[#All],2,FALSE) -> 42.715954 | L12: =VLOOKUP(A12,Table1[],5,FALSE) -> 41.132147 | M12: =0.943*L12 + 0.0717 -> 38.859315 | W12: 42.715954 | X12: 44.107295 | Y12: =0.942*X12 + 0.0844 -> 41.633471
A13: S0012 | B13: =VLOOKUP(A13,Table1[#All],2,FALSE) -> 76.547557 | C13: =VLOOKUP(A13,Table1[#All],10,FALSE) -> 87.639418 | D13: =0.4892*C13 + 38.572 -> 81.445203 | K13: =VLOOKUP(A13,Table1[#All],2,FALSE) -> 76.547557 | L13: =VLOOKUP(A13,Table1[],5,FALSE) -> 93.345042 | M13: =0.943*L13 + 0.0717 -> 88.096074 | W13: 76.547557 | X13: 90.557927 | Y13: =0.942*X13 + 0.0844 -> 85.389967
... A1001: S1000 | B1001: =VLOOKUP(A1001,Table1[#All],2,FALSE) -> 64.350338 | C1001: =VLOOKUP(A1001,Table1[#All],10,FALSE) -> 75.801316 | D1001: =0.4892*C1001 + 38.572 -> 75.654004 | K1001: =VLOOKUP(A1001,Table1[#All],2,FALSE) -> 64.350338 | L1001: =VLOOKUP(A1001,Table1[],5,FALSE) -> 64.530318 | M1001: =0.943*L1001 + 0.0717 -> 60.923789 | W1001: 64.350338 | X1001: 64.099969 | Y1001: =0.942*X1001 + 0.0844 -> 60.466571

Sheet Regression 01
A1: previous_score | B1: final_score | F1: SUMMARY OUTPUT
A2: 60.599707 | B2: 60.137241 | C2: =$G$17+A2*$G$18 -> 66.130361
A3: 92.289287 | B3: 99.021977 | C3: =$G$17+A3*$G$18 -> 90.054365 | F3: Regression Statistics
A4: 80.259667 | B4: 70.522955 | C4: =$G$17+A4*$G$18 -> 80.97262 | F4: Multiple R | G4: 0.84375515
A5: 72.926217 | B5: 63.448537 | C5: =$G$17+A5*$G$18 -> 75.436243 | F5: R Square | G5: 0.71192275
A6: 48.581025 | B6: 66.483019 | C6: =$G$17+A6*$G$18 -> 57.056875 | F6: Adjusted R Square | G6: 0.7116341
A7: 48.579699 | B7: 49.088061 | C7: =$G$17+A7*$G$18 -> 57.055874 | F7: Standard Error | G7: 7.7200955
A8: 43.194599 | B8: 48.453234 | C8: =$G$17+A8*$G$18 -> 52.9904 | F8: Observations | G8: 1000
A9: 87.639688 | B9: 84.613576 | C9: =$G$17+A9*$G$18 -> 86.544157
A10: 73.061326 | B10: 66.451909 | C10: =$G$17+A10*$G$18 -> 75.538243 | F10: ANOVA
A11: 78.943992 | B11: 74.20951 | C11: =$G$17+A11*$G$18 -> 79.979353 | G11: df | H11: SS | I11: MS | J11: F | K11: Significance F
A12: 41.132147 | B12: 42.715954 | C12: =$G$17+A12*$G$18 -> 51.433355 | F12: Regression | G12: 1 | H12: 146994.07 | I12: 146994.07 | J12: 2466.3486 | K12: 5.8999021e-272
A13: 93.345042 | B13: 76.547557 | C13: =$G$17+A13*$G$18 -> 90.851405 | F13: Residual | G13: 998 | H13: 59480.675 | I13: 59.599875
A14: 85.784345 | B14: 97.925131 | C14: =$G$17+A14*$G$18 -> 85.143468 | F14: Total | G14: 999 | H14: 206474.74
A15: 51.678651 | B15: 56.731838 | C15: =$G$17+A15*$G$18 -> 59.395423
A16: 50.000373 | B16: 55.269319 | C16: =$G$17+A16*$G$18 -> 58.12841 | G16: Coefficients | H16: Standard Error | I16: t Stat | J16: P-value | K16: Lower 95% | L16: Upper 95% | M16: Lower 95.0% | N16: Upper 95.0%
A17: 50.087248 | B17: 58.383835 | C17: =$G$17+A17*$G$18 -> 58.193996 | F17: Intercept | G17: 20.3807 | H17: 1.0468284 | I17: 19.468997 | J17: 8.1804198e-72 | K17: 18.326462 | L17: 22.434937 | M17: 18.326462 | N17: 22.434937
A18: 56.733323 | B18: 53.472483 | C18: =$G$17+A18*$G$18 -> 63.211441 | E18: Slop | F18: previous_score | G18: 0.75494857 | H18: 0.015201629 | I18: 49.662346 | J18: 5.8999021e-272 | K18: 0.72511774 | L18: 0.78477939 | M18: 0.72511774 | N18: 0.78477939
A19: 68.861604 | B19: 81.738245 | C19: =$G$17+A19*$G$18 -> 72.367669
A20: 63.756976 | B20: 61.010618 | C20: =$G$17+A20*$G$18 -> 68.513937
A21: 56.017603 | B21: 84.094984 | C21: =$G$17+A21*$G$18 -> 62.671109
A22: 73.651909 | B22: 63.394595 | C22: =$G$17+A22*$G$18 -> 75.984103 | F22: RESIDUAL OUTPUT | K22: PROBABILITY OUTPUT
A23: 47.672162 | B23: 74.755267 | C23: =$G$17+A23*$G$18 -> 56.37073
A24: 56.067956 | B24: 57.292057 | C24: =$G$17+A24*$G$18 -> 62.709123 | F24: Observation | G24: Predicted final_score | H24: Residuals | I24: Standard Residuals | K24: Percentile | L24: final_score
A25: 60.149901 | B25: 66.167282 | C25: =$G$17+A25*$G$18 -> 65.790782 | F25: 1 | G25: 66.130361 | H25: -5.9931206 | I25: -0.77669018 | K25: 0.05 | L25: 37.364699
A26: 65.083849 | B26: 77.100187 | C26: =$G$17+A26*$G$18 -> 69.515658 | F26: 2 | G26: 90.054365 | H26: 8.9676119 | I26: 1.1621752 | K26: 0.15 | L26: 37.760667
A27: 83.184678 | B27: 84.888241 | C27: =$G$17+A27*$G$18 -> 83.180853 | F27: 3 | G27: 80.97262 | H27: -10.449665 | I27: -1.3542448 | K27: 0.25 | L27: 39.136259
A28: 50.982058 | B28: 65.141653 | C28: =$G$17+A28*$G$18 -> 58.869531 | F28: 4 | G28: 75.436243 | H28: -11.987705 | I28: -1.5535701 | K28: 0.35 | L28: 39.353699
A29: 68.282894 | B29: 80.093884 | C29: =$G$17+A29*$G$18 -> 71.930773 | F29: 5 | G29: 57.056875 | H29: 9.4261436 | I29: 1.2215995 | K29: 0.45 | L29: 39.436637
A30: 72.582801 | B30: 84.428594 | C30: =$G$17+A30*$G$18 -> 75.176982 | F30: 6 | G30: 57.055874 | H30: -7.967813 | I30: -1.0326043 | K30: 0.55 | L30: 39.749455
A31: 42.554773 | B31: 55.652147 | C31: =$G$17+A31*$G$18 -> 52.507364 | F31: 7 | G31: 52.9904 | H31: -4.5371661 | I31: -0.58800292 | K31: 0.65 | L31: 39.835331
A32: 73.414967 | B32: 72.65991 | C32: =$G$17+A32*$G$18 -> 75.805224 | F32: 8 | G32: 86.544157 | H32: -1.9305805 | I32: -0.25019736 | K32: 0.75 | L32: 40.070262
A33: 49.378827 | B33: 48.135862 | C33: =$G$17+A33*$G$18 -> 57.659174 | F33: 9 | G33: 75.538243 | H33: -9.0863343 | I33: -1.1775613 | K33: 0.85 | L33: 40.793902
A34: 43.577838 | B34: 62.102769 | C34: =$G$17+A34*$G$18 -> 53.279726 | F34: 10 | G34: 79.979353 | H34: -5.7698436 | I34: -0.74775417 | K34: 0.95 | L34: 40.863183
A35: 92.188705 | B35: 96.662285 | C35: =$G$17+A35*$G$18 -> 89.97843 | F35: 11 | G35: 51.433355 | H35: -8.7174018 | I35: -1.1297487 | K35: 1.05 | L35: 41.233867
A36: 93.109762 | B36: 88.690649 | C36: =$G$17+A36*$G$18 -> 90.673781 | F36: 12 | G36: 90.851405 | H36: -14.303848 | I36: -1.8537352 | K36: 1.15 | L36: 41.787126
... A1001: 64.530318 | B1001: 64.350338 | C1001: =$G$17+A1001*$G$18 -> 69.097771 | F1001: 977 | G1001: 75.28757 | H1001: -7.1738211 | I1001: -0.92970538 | K1001: 97.65 | L1001: 99.014741
F1002: 978 | G1002: 52.713954 | H1002: -1.1207915 | I1002: -0.14525117 | K1002: 97.75 | L1002: 99.021977
F1003: 979 | G1003: 71.188847 | H1003: 2.8350912 | I1003: 0.36741918 | K1003: 97.85 | L1003: 99.164787
F1004: 980 | G1004: 75.360853 | H1004: 4.0902552 | I1004: 0.53008462 | K1004: 97.95 | L1004: 99.326703
...

Sheet Regression 02
A1: attendance_percentage | B1: final_score | F1: SUMMARY OUTPUT
A2: 75.738405 | B2: 60.137241 | C2: =$G$17+A2*$G$18 -> 73.501036
A3: 89.602736 | B3: 99.021977 | C3: =$G$17+A3*$G$18 -> 86.955804 | F3: Regression Statistics
A4: 81.495426 | B4: 70.522955 | C4: =$G$17+A4*$G$18 -> 79.08799 | F4: Multiple R | G4: 0.99079759
A5: 71.472047 | B5: 63.448537 | C5: =$G$17+A5*$G$18 -> 69.360709 | F5: R Square | G5: 0.98167986
A6: 64.276582 | B6: 66.483019 | C6: =$G$17+A6*$G$18 -> 62.377804 | F6: Adjusted R Square | G6: 0.98067886
A7: 61.624397 | B7: 49.088061 | C7: =$G$17+A7*$G$18 -> 59.803966 | F7: Standard Error | G7: 9.8011185
A8: 59.87698 | B8: 48.453234 | C8: =$G$17+A8*$G$18 -> 58.108169 | F8: Observations | G8: 1000
A9: 81.947173 | B9: 84.613576 | C9: =$G$17+A9*$G$18 -> 79.526392
A10: 71.631035 | B10: 66.451909 | C10: =$G$17+A10*$G$18 -> 69.515 | F10: ANOVA
A11: 69.685303 | B11: 74.20951 | C11: =$G$17+A11*$G$18 -> 67.626747 | G11: df | H11: SS | I11: MS | J11: F | K11: Significance F
A12: 57.225358 | B12: 42.715954 | C12: =$G$17+A12*$G$18 -> 55.534878 | F12: Regression | G12: 1 | H12: 5142305.7 | I12: 5142305.7 | J12: 53531.154 | K12: 0
A13: 87.639418 | B13: 76.547557 | C13: =$G$17+A13*$G$18 -> 85.050484 | F13: Residual | G13: 999 | H13: 95965.862 | I13: 96.061924
A14: 76.151287 | B14: 97.925131 | C14: =$G$17+A14*$G$18 -> 73.901721 | F14: Total | G14: 1000 | H14: 5238271.5
A15: 65.917737 | B15: 56.731838 | C15: =$G$17+A15*$G$18 -> 63.970477
A16: 74.501529 | B16: 55.269319 | C16: =$G$17+A16*$G$18 -> 72.300698 | G16: Coefficients | H16: Standard Error | I16: t Stat | J16: P-value | K16: Lower 95% | L16: Upper 95% | M16: Lower 95.0% | N16: Upper 95.0%
A17: 70.158907 | B17: 58.383835 | C17: =$G$17+A17*$G$18 -> 68.08636 | F17: Intercept | G17: 0 | H17: #N/A | I17: #N/A | J17: #N/A | K17: #N/A | L17: #N/A | M17: #N/A | N17: #N/A
A18: 76.584369 | B18: 53.472483 | C18: =$G$17+A18*$G$18 -> 74.322009 | E18: Slop | F18: attendance_percentage | G18: 0.97045925 | H18: 0.0041944401 | I18: 231.36801 | J18: 0 | K18: 0.96222833 | L18: 0.97869017 | M18: 0.96222833 | N18: 0.97869017
A19: 76.386441 | B19: 81.738245 | C19: =$G$17+A19*$G$18 -> 74.129928
A20: 77.716037 | B20: 61.010618 | C20: =$G$17+A20*$G$18 -> 75.420247
A21: 64.388978 | B21: 84.094984 | C21: =$G$17+A21*$G$18 -> 62.486879
A22: 73.604253 | B22: 63.394595 | C22: =$G$17+A22*$G$18 -> 71.429928 | F22: RESIDUAL OUTPUT | K22: PROBABILITY OUTPUT
A23: 50.14038 | B23: 74.755267 | C23: =$G$17+A23*$G$18 -> 48.659196
A24: 73.964705 | B24: 57.292057 | C24: =$G$17+A24*$G$18 -> 71.779732 | F24: Observation | G24: Predicted final_score | H24: Residuals | I24: Standard Residuals | K24: Percentile | L24: final_score
A25: 77.776571 | B25: 66.167282 | C25: =$G$17+A25*$G$18 -> 75.478992 | F25: 1 | G25: 73.501036 | H25: -13.363795 | I25: -1.3641792 | K25: 0.05 | L25: 37.364699
A26: 69.776038 | B26: 77.100187 | C26: =$G$17+A26*$G$18 -> 67.714802 | F26: 2 | G26: 86.955804 | H26: 12.066172 | I26: 1.2317176 | K26: 0.15 | L26: 37.760667
A27: 80.32258 | B27: 84.888241 | C27: =$G$17+A27*$G$18 -> 77.949791 | F27: 3 | G27: 79.08799 | H27: -8.5650346 | I27: -0.87432065 | K27: 0.25 | L27: 39.136259
A28: 61.721718 | B28: 65.141653 | C28: =$G$17+A28*$G$18 -> 59.898413 | F28: 4 | G28: 69.360709 | H28: -5.9121718 | I28: -0.60351582 | K28: 0.35 | L28: 39.353699
A29: 76.054715 | B29: 80.093884 | C29: =$G$17+A29*$G$18 -> 73.808001 | F29: 5 | G29: 62.377804 | H29: 4.1052152 | I29: 0.41906129 | K29: 0.45 | L29: 39.436637
A30: 81.916063 | B30: 84.428594 | C30: =$G$17+A30*$G$18 -> 79.496201 | F30: 6 | G30: 59.803966 | H30: -10.715906 | I30: -1.0938821 | K30: 0.55 | L30: 39.749455
A31: 52.563526 | B31: 55.652147 | C31: =$G$17+A31*$G$18 -> 51.01076 | F31: 7 | G31: 58.108169 | H31: -9.6549346 | I31: -0.98557789 | K31: 0.65 | L31: 39.835331
A32: 78.754676 | B32: 72.65991 | C32: =$G$17+A32*$G$18 -> 76.428204 | F32: 8 | G32: 79.526392 | H32: 5.0871839 | I32: 0.51930087 | K32: 0.75 | L32: 40.070262
A33: 63.306055 | B33: 48.135862 | C33: =$G$17+A33*$G$18 -> 61.435946 | F33: 9 | G33: 69.515 | H33: -3.0630918 | I33: -0.3126811 | K33: 0.85 | L33: 40.793902
A34: 62.355891 | B34: 62.102769 | C34: =$G$17+A34*$G$18 -> 60.513851 | F34: 10 | G34: 67.626747 | H34: 6.5827628 | I34: 0.6719699 | K34: 0.95 | L34: 40.863183
A35: 88.389322 | B35: 96.662285 | C35: =$G$17+A35*$G$18 -> 85.778235 | F35: 11 | G35: 55.534878 | H35: -12.818925 | I35: -1.3085587 | K35: 1.05 | L35: 41.233867
A36: 85.613869 | B36: 88.690649 | C36: =$G$17+A36*$G$18 -> 83.084771 | F36: 12 | G36: 85.050484 | H36: -8.5029267 | I36: -0.86798067 | K36: 1.15 | L36: 41.787126
... A1001: 75.801316 | B1001: 64.350338 | C1001: =$G$17+A1001*$G$18 -> 73.562088 | F1001: 977 | G1001: 65.612522 | H1001: 2.501227 | I1001: 0.25532582 | K1001: 97.65 | L1001: 99.014741
F1002: 978 | G1002: 58.738745 | H1002: -7.1455824 | I1002: -0.72942266 | K1002: 97.75 | L1002: 99.021977
F1003: 979 | G1003: 71.874425 | H1003: 2.1495127 | I1003: 0.21942273 | K1003: 97.85 | L1003: 99.164787
F1004: 980 | G1004: 72.363832 | H1004: 7.087277 | I1004: 0.72347082 | K1004: 97.95 | L1004: 99.326703
...

Sheet Regression 03
A1: language_prev_score | B1: final_score | C1: Regression 03 | D1: Regression 02 | E1: Regression 01 | F1: Average | G1: Percentage | J1: SUMMARY OUTPUT
A2: 64.972292 | B2: 60.137241 | C2: =$K$17+A2*$K$18 -> 67.503936 | D2: ='Regression 02'!C2 -> 73.501036 | E2: ='Regression 01'!C2 -> 66.130361 | F2: =AVERAGE(C2:E2) -> 69.045111 | G2: =F2/B2 -> 1.1481257
A3: 89.040461 | B3: 99.021977 | C3: =$K$17+A3*$K$18 -> 92.509921 | D3: ='Regression 02'!C3 -> 86.955804 | E3: ='Regression 01'!C3 -> 90.054365 | F3: =AVERAGE(C3:E3) -> 89.84003 | G3: =F3/B3 -> 0.90727365 | J3: Regression Statistics
A4: 74.243663 | B4: 70.522955 | C4: =$K$17+A4*$K$18 -> 77.136566 | D4: ='Regression 02'!C4 -> 79.08799 | E4: ='Regression 01'!C4 -> 80.97262 | F4: =AVERAGE(C4:E4) -> 79.065725 | G4: =F4/B4 -> 1.1211346 | J4: Multiple R | K4: 0.98990066
A5: 67.715995 | B5: 63.448537 | C5: =$K$17+A5*$K$18 -> 70.354547 | D5: ='Regression 02'!C5 -> 69.360709 | E5: ='Regression 01'!C5 -> 75.436243 | F5: =AVERAGE(C5:E5) -> 71.717166 | G5: =F5/B5 -> 1.1303202 | J5: R Square | K5: 0.97990333
A6: 46.145011 | B6: 66.483019 | C6: =$K$17+A6*$K$18 -> 47.94305 | D6: ='Regression 02'!C6 -> 62.377804 | E6: ='Regression 01'!C6 -> 57.056875 | F6: =AVERAGE(C6:E6) -> 55.792576 | G6: =F6/B6 -> 0.83920041 | J6: Adjusted R Square | K6: 0.97890232
A7: 46.820092 | B7: 49.088061 | C7: =$K$17+A7*$K$18 -> 48.644436 | D7: ='Regression 02'!C7 -> 59.803966 | E7: ='Regression 01'!C7 -> 57.055874 | F7: =AVERAGE(C7:E7) -> 55.168092 | G7: =F7/B7 -> 1.1238597 | J7: Standard Error | K7: 10.26534
A8: 39.344618 | B8: 48.453234 | C8: =$K$17+A8*$K$18 -> 40.877681 | D8: ='Regression 02'!C8 -> 58.108169 | E8: ='Regression 01'!C8 -> 52.9904 | F8: =AVERAGE(C8:E8) -> 50.65875 | G8: =F8/B8 -> 1.0455184 | J8: Observations | K8: 1000
A9: 81.159105 | B9: 84.613576 | C9: =$K$17+A9*$K$18 -> 84.321468 | D9: ='Regression 02'!C9 -> 79.526392 | E9: ='Regression 01'!C9 -> 86.544157 | F9: =AVERAGE(C9:E9) -> 83.464006 | G9: =F9/B9 -> 0.98641388
A10: 70.780722 | B10: 66.451909 | C10: =$K$17+A10*$K$18 -> 73.538691 | D10: ='Regression 02'!C10 -> 69.515 | E10: ='Regression 01'!C10 -> 75.538243 | F10: =AVERAGE(C10:E10) -> 72.863978 | G10: =F10/B10 -> 1.0964919 | J10: ANOVA
A11: 79.851125 | B11: 74.20951 | C11: =$K$17+A11*$K$18 -> 82.962523 | D11: ='Regression 02'!C11 -> 67.626747 | E11: ='Regression 01'!C11 -> 79.979353 | F11: =AVERAGE(C11:E11) -> 76.856208 | G11: =F11/B11 -> 1.0356652 | K11: df | L11: SS | M11: MS | N11: F | O11: Significance F
A12: 44.107295 | B12: 42.715954 | C12: =$K$17+A12*$K$18 -> 45.825935 | D12: ='Regression 02'!C12 -> 55.534878 | E12: ='Regression 01'!C12 -> 51.433355 | F12: =AVERAGE(C12:E12) -> 50.931389 | G12: =F12/B12 -> 1.1923271 | J12: Regression | K12: 1 | L12: 5132999.7 | M12: 5132999.7 | N12: 48710.718 | O12: 0
A13: 90.557927 | B13: 76.547557 | C13: =$K$17+A13*$K$18 -> 94.086515 | D13: ='Regression 02'!C13 -> 85.050484 | E13: ='Regression 01'!C13 -> 90.851405 | F13: =AVERAGE(C13:E13) -> 89.996135 | G13: =F13/B13 -> 1.1756892 | J13: Residual | K13: 999 | L13: 105271.84 | M13: 105.37721
A14: 83.719356 | B14: 97.925131 | C14: =$K$17+A14*$K$18 -> 86.98148 | D14: ='Regression 02'!C14 -> 73.901721 | E14: ='Regression 01'!C14 -> 85.143468 | F14: =AVERAGE(C14:E14) -> 82.00889 | G14: =F14/B14 -> 0.83746521 | J14: Total | K14: 1000 | L14: 5238271.5
A15: 47.04516 | B15: 56.731838 | C15: =$K$17+A15*$K$18 -> 48.878274 | D15: ='Regression 02'!C15 -> 63.970477 | E15: ='Regression 01'!C15 -> 59.395423 | F15: =AVERAGE(C15:E15) -> 57.414725 | G15: =F15/B15 -> 1.0120371
A16: 49.843177 | B16: 55.269319 | C16: =$K$17+A16*$K$18 -> 51.785316 | D16: ='Regression 02'!C16 -> 72.300698 | E16: ='Regression 01'!C16 -> 58.12841 | F16: =AVERAGE(C16:E16) -> 60.738141 | G16: =F16/B16 -> 1.0989486 | K16: Coefficients | L16: Standard Error | M16: t Stat | N16: P-value | O16: Lower 95% | P16: Upper 95% | Q16: Lower 95.0% | R16: Upper 95.0%
A17: 45.845105 | B17: 58.383835 | C17: =$K$17+A17*$K$18 -> 47.631459 | D17: ='Regression 02'!C17 -> 68.08636 | E17: ='Regression 01'!C17 -> 58.193996 | F17: =AVERAGE(C17:E17) -> 57.970605 | G17: =F17/B17 -> 0.99292219 | J17: Intercept | K17: 0 | L17: #N/A | M17: #N/A | N17: #N/A | O17: #N/A | P17: #N/A | Q17: #N/A | R17: #N/A
A18: 59.598962 | B18: 53.472483 | C18: =$K$17+A18*$K$18 -> 61.921235 | D18: ='Regression 02'!C18 -> 74.322009 | E18: ='Regression 01'!C18 -> 63.211441 | F18: =AVERAGE(C18:E18) -> 66.484895 | G18: =F18/B18 -> 1.2433478 | I18: Slop | J18: language_prev_score | K18: 1.038965 | L18: 0.0047074818 | M18: 220.70505 | N18: 0 | O18: 1.0297273 | P18: 1.0482027 | Q18: 1.0297273 | R18: 1.0482027
A19: 59.932271 | B19: 81.738245 | C19: =$K$17+A19*$K$18 -> 62.267531 | D19: ='Regression 02'!C19 -> 74.129928 | E19: ='Regression 01'!C19 -> 72.367669 | F19: =AVERAGE(C19:E19) -> 69.588376 | G19: =F19/B19 -> 0.85135638
A20: 61.958828 | B20: 61.010618 | C20: =$K$17+A20*$K$18 -> 64.373053 | D20: ='Regression 02'!C20 -> 75.420247 | E20: ='Regression 01'!C20 -> 68.513937 | F20: =AVERAGE(C20:E20) -> 69.435746 | G20: =F20/B20 -> 1.1380928
A21: 57.523139 | B21: 84.094984 | C21: =$K$17+A21*$K$18 -> 59.764528 | D21: ='Regression 02'!C21 -> 62.486879 | E21: ='Regression 01'!C21 -> 62.671109 | F21: =AVERAGE(C21:E21) -> 61.640838 | G21: =F21/B21 -> 0.73299067
A22: 74.571082 | B22: 63.394595 | C22: =$K$17+A22*$K$18 -> 77.476743 | D22: ='Regression 02'!C22 -> 71.429928 | E22: ='Regression 01'!C22 -> 75.984103 | F22: =AVERAGE(C22:E22) -> 74.963592 | G22: =F22/B22 -> 1.1824918 | J22: RESIDUAL OUTPUT | O22: PROBABILITY OUTPUT
A23: 61.137331 | B23: 74.755267 | C23: =$K$17+A23*$K$18 -> 63.519546 | D23: ='Regression 02'!C23 -> 48.659196 | E23: ='Regression 01'!C23 -> 56.37073 | F23: =AVERAGE(C23:E23) -> 56.183157 | G23: =F23/B23 -> 0.75156118
A24: 57.816956 | B24: 57.292057 | C24: =$K$17+A24*$K$18 -> 60.069793 | D24: ='Regression 02'!C24 -> 71.779732 | E24: ='Regression 01'!C24 -> 62.709123 | F24: =AVERAGE(C24:E24) -> 64.852883 | G24: =F24/B24 -> 1.1319699 | J24: Observation | K24: Predicted final_score | L24: Residuals | M24: Standard Residuals | O24: Percentile | P24: final_score
A25: 55.129628 | B25: 66.167282 | C25: =$K$17+A25*$K$18 -> 57.277754 | D25: ='Regression 02'!C25 -> 75.478992 | E25: ='Regression 01'!C25 -> 65.790782 | F25: =AVERAGE(C25:E25) -> 66.182509 | G25: =F25/B25 -> 1.0002301 | J25: 1 | K25: 67.503936 | L25: -7.3666956 | M25: -0.71798708 | O25: 0.05 | P25: 37.364699
A26: 64.606528 | B26: 77.100187 | C26: =$K$17+A26*$K$18 -> 67.12392 | D26: ='Regression 02'!C26 -> 67.714802 | E26: ='Regression 01'!C26 -> 69.515658 | F26: =AVERAGE(C26:E26) -> 68.118127 | G26: =F26/B26 -> 0.88350145 | J26: 2 | K26: 92.509921 | L26: 6.5120554 | M26: 0.63469048 | O26: 0.15 | P26: 37.760667
A27: 74.303446 | B27: 84.888241 | C27: =$K$17+A27*$K$18 -> 77.198679 | D27: ='Regression 02'!C27 -> 77.949791 | E27: ='Regression 01'!C27 -> 83.180853 | F27: =AVERAGE(C27:E27) -> 79.443108 | G27: =F27/B27 -> 0.93585527 | J27: 3 | K27: 77.136566 | L27: -6.613611 | M27: -0.64458849 | O27: 0.25 | P27: 39.136259
A28: 50.579059 | B28: 65.141653 | C28: =$K$17+A28*$K$18 -> 52.549872 | D28: ='Regression 02'!C28 -> 59.898413 | E28: ='Regression 01'!C28 -> 58.869531 | F28: =AVERAGE(C28:E28) -> 57.105939 | G28: =F28/B28 -> 0.87664245 | J28: 4 | K28: 70.354547 | L28: -6.9060102 | M28: -0.67308686 | O28: 0.35 | P28: 39.353699
A29: 64.117614 | B29: 80.093884 | C29: =$K$17+A29*$K$18 -> 66.615956 | D29: ='Regression 02'!C29 -> 73.808001 | E29: ='Regression 01'!C29 -> 71.930773 | F29: =AVERAGE(C29:E29) -> 70.78491 | G29: =F29/B29 -> 0.88377422 | J29: 5 | K29: 47.94305 | L29: 18.539968 | M29: 1.8069781 | O29: 0.45 | P29: 39.436637
A30: 77.159753 | B30: 84.428594 | C30: =$K$17+A30*$K$18 -> 80.166281 | D30: ='Regression 02'!C30 -> 79.496201 | E30: ='Regression 01'!C30 -> 75.176982 | F30: =AVERAGE(C30:E30) -> 78.279821 | G30: =F30/B30 -> 0.92717192 | J30: 6 | K30: 48.644436 | L30: 0.44362426 | M30: 0.043237362 | O30: 0.55 | P30: 39.749455
A31: 39.807071 | B31: 55.652147 | C31: =$K$17+A31*$K$18 -> 41.358153 | D31: ='Regression 02'!C31 -> 51.01076 | E31: ='Regression 01'!C31 -> 52.507364 | F31: =AVERAGE(C31:E31) -> 48.292093 | G31: =F31/B31 -> 0.86774897 | J31: 7 | K31: 40.877681 | L31: 7.5755531 | M31: 0.73834315 | O31: 0.65 | P31: 39.835331
A32: 72.831137 | B32: 72.65991 | C32: =$K$17+A32*$K$18 -> 75.669002 | D32: ='Regression 02'!C32 -> 76.428204 | E32: ='Regression 01'!C32 -> 75.805224 | F32: =AVERAGE(C32:E32) -> 75.967476 | G32: =F32/B32 -> 1.0455212 | J32: 8 | K32: 84.321468 | L32: 0.29210794 | M32: 0.028469986 | O32: 0.75 | P32: 40.070262
A33: 46.201038 | B33: 48.135862 | C33: =$K$17+A33*$K$18 -> 48.00126 | D33: ='Regression 02'!C33 -> 61.435946 | E33: ='Regression 01'!C33 -> 57.659174 | F33: =AVERAGE(C33:E33) -> 55.698794 | G33: =F33/B33 -> 1.1571164 | J33: 9 | K33: 73.538691 | L33: -7.0867828 | M33: -0.69070568 | O33: 0.85 | P33: 40.793902
A34: 52.272094 | B34: 62.102769 | C34: =$K$17+A34*$K$18 -> 54.308876 | D34: ='Regression 02'!C34 -> 60.513851 | E34: ='Regression 01'!C34 -> 53.279726 | F34: =AVERAGE(C34:E34) -> 56.034151 | G34: =F34/B34 -> 0.90228104 | J34: 10 | K34: 82.962523 | L34: -8.7530134 | M34: -0.85310305 | O34: 0.95 | P34: 40.863183
A35: 90.582491 | B35: 96.662285 | C35: =$K$17+A35*$K$18 -> 94.112036 | D35: ='Regression 02'!C35 -> 85.778235 | E35: ='Regression 01'!C35 -> 89.97843 | F35: =AVERAGE(C35:E35) -> 89.956234 | G35: =F35/B35 -> 0.93062392 | J35: 11 | K35: 45.825935 | L35: -3.1099811 | M35: -0.30311097 | O35: 1.05 | P35: 41.233867
A36: 102.27255 | B36: 88.690649 | C36: =$K$17+A36*$K$18 -> 106.2576 | D36: ='Regression 02'!C36 -> 83.084771 | E36: ='Regression 01'!C36 -> 90.673781 | F36: =AVERAGE(C36:E36) -> 93.338716 | G36: =F36/B36 -> 1.0524076 | J36: 12 | K36: 94.086515 | L36: -17.538958 | M36: -1.7094157 | O36: 1.15 | P36: 41.787126
... A1001: 64.099969 | B1001: 64.350338 | C1001: =$K$17+A1001*$K$18 -> 66.597624 | D1001: ='Regression 02'!C1001 -> 73.562088 | E1001: ='Regression 01'!C1001 -> 69.097771 | F1001: =AVERAGE(C1001:E1001) -> 69.752494 | G1001: =F1001/B1001 -> 1.0839492 | J1001: 977 | K1001: 76.100525 | L1001: -7.9867759 | M1001: -0.77842253 | O1001: 97.65 | P1001: 99.014741
J1002: 978 | K1002: 55.105456 | L1002: -3.5122937 | M1002: -0.34232194 | O1002: 97.75 | P1002: 99.021977
J1003: 979 | K1003: 71.363321 | L1003: 2.6606164 | M1003: 0.25931412 | O1003: 97.85 | P1003: 99.164787
J1004: 980 | K1004: 75.548299 | L1004: 3.9028092 | M1004: 0.38038311 | O1004: 97.95 | P1004: 99.326703
...
